Traceback (most recent call last):
  File "/Users/brenda/opt/anaconda3/envs/jb/lib/python3.10/site-packages/jupyter_cache/executors/utils.py", line 51, in single_nb_execution
    executenb(
  File "/Users/brenda/opt/anaconda3/envs/jb/lib/python3.10/site-packages/nbclient/client.py", line 1204, in execute
    return NotebookClient(nb=nb, resources=resources, km=km, **kwargs).execute()
  File "/Users/brenda/opt/anaconda3/envs/jb/lib/python3.10/site-packages/nbclient/util.py", line 84, in wrapped
    return just_run(coro(*args, **kwargs))
  File "/Users/brenda/opt/anaconda3/envs/jb/lib/python3.10/site-packages/nbclient/util.py", line 62, in just_run
    return loop.run_until_complete(coro)
  File "/Users/brenda/opt/anaconda3/envs/jb/lib/python3.10/asyncio/base_events.py", line 649, in run_until_complete
    return future.result()
  File "/Users/brenda/opt/anaconda3/envs/jb/lib/python3.10/site-packages/nbclient/client.py", line 663, in async_execute
    await self.async_execute_cell(
  File "/Users/brenda/opt/anaconda3/envs/jb/lib/python3.10/site-packages/nbclient/client.py", line 965, in async_execute_cell
    await self._check_raise_for_error(cell, cell_index, exec_reply)
  File "/Users/brenda/opt/anaconda3/envs/jb/lib/python3.10/site-packages/nbclient/client.py", line 862, in _check_raise_for_error
    raise CellExecutionError.from_cell_and_msg(cell, exec_reply_content)
nbclient.exceptions.CellExecutionError: An error occurred while executing the following cell:
------------------
# Descomentar estas lÃ­neas si estÃ¡ en modo online

#!pip install pyscf

import pyscf
import numpy as np
from scipy.linalg import eigh
import sympy as sp
sp.init_printing()
------------------

[0;31m---------------------------------------------------------------------------[0m
[0;31mOSError[0m                                   Traceback (most recent call last)
File [0;32m~/opt/anaconda3/envs/jb/lib/python3.10/site-packages/pyscf/lib/misc.py:55[0m, in [0;36mload_library[0;34m(libname)[0m
[1;32m     54[0m     _loaderpath [38;5;241m=[39m os[38;5;241m.[39mpath[38;5;241m.[39mdirname([38;5;18m__file__[39m)
[0;32m---> 55[0m     [38;5;28;01mreturn[39;00m [43mnumpy[49m[38;5;241;43m.[39;49m[43mctypeslib[49m[38;5;241;43m.[39;49m[43mload_library[49m[43m([49m[43mlibname[49m[43m,[49m[43m [49m[43m_loaderpath[49m[43m)[49m
[1;32m     56[0m [38;5;28;01mexcept[39;00m [38;5;167;01mOSError[39;00m:

File [0;32m~/opt/anaconda3/envs/jb/lib/python3.10/site-packages/numpy/ctypeslib.py:158[0m, in [0;36mload_library[0;34m(libname, loader_path)[0m
[1;32m    157[0m [38;5;28;01mtry[39;00m:
[0;32m--> 158[0m     [38;5;28;01mreturn[39;00m [43mctypes[49m[38;5;241;43m.[39;49m[43mcdll[49m[43m[[49m[43mlibpath[49m[43m][49m
[1;32m    159[0m [38;5;28;01mexcept[39;00m [38;5;167;01mOSError[39;00m:
[1;32m    160[0m     [38;5;66;03m## defective lib file[39;00m

File [0;32m~/opt/anaconda3/envs/jb/lib/python3.10/ctypes/__init__.py:449[0m, in [0;36mLibraryLoader.__getitem__[0;34m(self, name)[0m
[1;32m    448[0m [38;5;28;01mdef[39;00m [38;5;21m__getitem__[39m([38;5;28mself[39m, name):
[0;32m--> 449[0m     [38;5;28;01mreturn[39;00m [38;5;28;43mgetattr[39;49m[43m([49m[38;5;28;43mself[39;49m[43m,[49m[43m [49m[43mname[49m[43m)[49m

File [0;32m~/opt/anaconda3/envs/jb/lib/python3.10/ctypes/__init__.py:444[0m, in [0;36mLibraryLoader.__getattr__[0;34m(self, name)[0m
[1;32m    443[0m     [38;5;28;01mraise[39;00m [38;5;167;01mAttributeError[39;00m(name)
[0;32m--> 444[0m dll [38;5;241m=[39m [38;5;28;43mself[39;49m[38;5;241;43m.[39;49m[43m_dlltype[49m[43m([49m[43mname[49m[43m)[49m
[1;32m    445[0m [38;5;28msetattr[39m([38;5;28mself[39m, name, dll)

File [0;32m~/opt/anaconda3/envs/jb/lib/python3.10/ctypes/__init__.py:374[0m, in [0;36mCDLL.__init__[0;34m(self, name, mode, handle, use_errno, use_last_error, winmode)[0m
[1;32m    373[0m [38;5;28;01mif[39;00m handle [38;5;129;01mis[39;00m [38;5;28;01mNone[39;00m:
[0;32m--> 374[0m     [38;5;28mself[39m[38;5;241m.[39m_handle [38;5;241m=[39m [43m_dlopen[49m[43m([49m[38;5;28;43mself[39;49m[38;5;241;43m.[39;49m[43m_name[49m[43m,[49m[43m [49m[43mmode[49m[43m)[49m
[1;32m    375[0m [38;5;28;01melse[39;00m:

[0;31mOSError[0m: dlopen(/Users/brenda/opt/anaconda3/envs/jb/lib/python3.10/site-packages/pyscf/lib/libnp_helper.dylib, 6): Library not loaded: /usr/local/opt/libomp/lib/libomp.dylib
  Referenced from: /Users/brenda/opt/anaconda3/envs/jb/lib/python3.10/site-packages/pyscf/lib/libnp_helper.dylib
  Reason: image not found

During handling of the above exception, another exception occurred:

[0;31mOSError[0m                                   Traceback (most recent call last)
Cell [0;32mIn[1], line 5[0m
[1;32m      1[0m [38;5;66;03m# Descomentar estas lÃ­neas si estÃ¡ en modo online[39;00m
[1;32m      2[0m 
[1;32m      3[0m [38;5;66;03m#!pip install pyscf[39;00m
[0;32m----> 5[0m [38;5;28;01mimport[39;00m [38;5;21;01mpyscf[39;00m
[1;32m      6[0m [38;5;28;01mimport[39;00m [38;5;21;01mnumpy[39;00m [38;5;28;01mas[39;00m [38;5;21;01mnp[39;00m
[1;32m      7[0m [38;5;28;01mfrom[39;00m [38;5;21;01mscipy[39;00m[38;5;21;01m.[39;00m[38;5;21;01mlinalg[39;00m [38;5;28;01mimport[39;00m eigh

File [0;32m~/opt/anaconda3/envs/jb/lib/python3.10/site-packages/pyscf/__init__.py:113[0m
[1;32m    110[0m     _internal[38;5;241m.[39m_get_void_ptr [38;5;241m=[39m _get_void_ptr
[1;32m    112[0m [38;5;28;01mfrom[39;00m [38;5;21;01mpyscf[39;00m [38;5;28;01mimport[39;00m __config__
[0;32m--> 113[0m [38;5;28;01mfrom[39;00m [38;5;21;01mpyscf[39;00m [38;5;28;01mimport[39;00m lib
[1;32m    114[0m [38;5;28;01mfrom[39;00m [38;5;21;01mpyscf[39;00m [38;5;28;01mimport[39;00m gto
[1;32m    115[0m [38;5;28;01mfrom[39;00m [38;5;21;01mpyscf[39;00m [38;5;28;01mimport[39;00m scf

File [0;32m~/opt/anaconda3/envs/jb/lib/python3.10/site-packages/pyscf/lib/__init__.py:24[0m
[1;32m     22[0m [38;5;28;01mfrom[39;00m [38;5;21;01mpyscf[39;00m[38;5;21;01m.[39;00m[38;5;21;01mlib[39;00m [38;5;28;01mimport[39;00m parameters
[1;32m     23[0m param [38;5;241m=[39m parameters
[0;32m---> 24[0m [38;5;28;01mfrom[39;00m [38;5;21;01mpyscf[39;00m[38;5;21;01m.[39;00m[38;5;21;01mlib[39;00m [38;5;28;01mimport[39;00m numpy_helper
[1;32m     25[0m [38;5;28;01mfrom[39;00m [38;5;21;01mpyscf[39;00m[38;5;21;01m.[39;00m[38;5;21;01mlib[39;00m [38;5;28;01mimport[39;00m linalg_helper
[1;32m     26[0m [38;5;28;01mfrom[39;00m [38;5;21;01mpyscf[39;00m[38;5;21;01m.[39;00m[38;5;21;01mlib[39;00m [38;5;28;01mimport[39;00m scipy_helper

File [0;32m~/opt/anaconda3/envs/jb/lib/python3.10/site-packages/pyscf/lib/numpy_helper.py:39[0m
[1;32m     36[0m [38;5;28;01mexcept[39;00m ([38;5;167;01mImportError[39;00m, [38;5;167;01mOSError[39;00m):
[1;32m     37[0m     FOUND_TBLIS [38;5;241m=[39m [38;5;28;01mFalse[39;00m
[0;32m---> 39[0m _np_helper [38;5;241m=[39m [43mmisc[49m[38;5;241;43m.[39;49m[43mload_library[49m[43m([49m[38;5;124;43m'[39;49m[38;5;124;43mlibnp_helper[39;49m[38;5;124;43m'[39;49m[43m)[49m
[1;32m     41[0m BLOCK_DIM [38;5;241m=[39m [38;5;241m192[39m
[1;32m     42[0m PLAIN [38;5;241m=[39m [38;5;241m0[39m

File [0;32m~/opt/anaconda3/envs/jb/lib/python3.10/site-packages/pyscf/lib/misc.py:63[0m, in [0;36mload_library[0;34m(libname)[0m
[1;32m     61[0m         [38;5;28;01mfor[39;00m files [38;5;129;01min[39;00m os[38;5;241m.[39mlistdir(libpath):
[1;32m     62[0m             [38;5;28;01mif[39;00m files[38;5;241m.[39mstartswith(libname):
[0;32m---> 63[0m                 [38;5;28;01mreturn[39;00m [43mnumpy[49m[38;5;241;43m.[39;49m[43mctypeslib[49m[38;5;241;43m.[39;49m[43mload_library[49m[43m([49m[43mlibname[49m[43m,[49m[43m [49m[43mlibpath[49m[43m)[49m
[1;32m     64[0m [38;5;28;01mraise[39;00m

File [0;32m~/opt/anaconda3/envs/jb/lib/python3.10/site-packages/numpy/ctypeslib.py:158[0m, in [0;36mload_library[0;34m(libname, loader_path)[0m
[1;32m    156[0m [38;5;28;01mif[39;00m os[38;5;241m.[39mpath[38;5;241m.[39mexists(libpath):
[1;32m    157[0m     [38;5;28;01mtry[39;00m:
[0;32m--> 158[0m         [38;5;28;01mreturn[39;00m [43mctypes[49m[38;5;241;43m.[39;49m[43mcdll[49m[43m[[49m[43mlibpath[49m[43m][49m
[1;32m    159[0m     [38;5;28;01mexcept[39;00m [38;5;167;01mOSError[39;00m:
[1;32m    160[0m         [38;5;66;03m## defective lib file[39;00m
[1;32m    161[0m         [38;5;28;01mraise[39;00m

File [0;32m~/opt/anaconda3/envs/jb/lib/python3.10/ctypes/__init__.py:449[0m, in [0;36mLibraryLoader.__getitem__[0;34m(self, name)[0m
[1;32m    448[0m [38;5;28;01mdef[39;00m [38;5;21m__getitem__[39m([38;5;28mself[39m, name):
[0;32m--> 449[0m     [38;5;28;01mreturn[39;00m [38;5;28;43mgetattr[39;49m[43m([49m[38;5;28;43mself[39;49m[43m,[49m[43m [49m[43mname[49m[43m)[49m

File [0;32m~/opt/anaconda3/envs/jb/lib/python3.10/ctypes/__init__.py:444[0m, in [0;36mLibraryLoader.__getattr__[0;34m(self, name)[0m
[1;32m    442[0m [38;5;28;01mif[39;00m name[[38;5;241m0[39m] [38;5;241m==[39m [38;5;124m'[39m[38;5;124m_[39m[38;5;124m'[39m:
[1;32m    443[0m     [38;5;28;01mraise[39;00m [38;5;167;01mAttributeError[39;00m(name)
[0;32m--> 444[0m dll [38;5;241m=[39m [38;5;28;43mself[39;49m[38;5;241;43m.[39;49m[43m_dlltype[49m[43m([49m[43mname[49m[43m)[49m
[1;32m    445[0m [38;5;28msetattr[39m([38;5;28mself[39m, name, dll)
[1;32m    446[0m [38;5;28;01mreturn[39;00m dll

File [0;32m~/opt/anaconda3/envs/jb/lib/python3.10/ctypes/__init__.py:374[0m, in [0;36mCDLL.__init__[0;34m(self, name, mode, handle, use_errno, use_last_error, winmode)[0m
[1;32m    371[0m [38;5;28mself[39m[38;5;241m.[39m_FuncPtr [38;5;241m=[39m _FuncPtr
[1;32m    373[0m [38;5;28;01mif[39;00m handle [38;5;129;01mis[39;00m [38;5;28;01mNone[39;00m:
[0;32m--> 374[0m     [38;5;28mself[39m[38;5;241m.[39m_handle [38;5;241m=[39m [43m_dlopen[49m[43m([49m[38;5;28;43mself[39;49m[38;5;241;43m.[39;49m[43m_name[49m[43m,[49m[43m [49m[43mmode[49m[43m)[49m
[1;32m    375[0m [38;5;28;01melse[39;00m:
[1;32m    376[0m     [38;5;28mself[39m[38;5;241m.[39m_handle [38;5;241m=[39m handle

[0;31mOSError[0m: dlopen(/Users/brenda/opt/anaconda3/envs/jb/lib/python3.10/site-packages/pyscf/lib/libnp_helper.dylib, 6): Library not loaded: /usr/local/opt/libomp/lib/libomp.dylib
  Referenced from: /Users/brenda/opt/anaconda3/envs/jb/lib/python3.10/site-packages/pyscf/lib/libnp_helper.dylib
  Reason: image not found
OSError: dlopen(/Users/brenda/opt/anaconda3/envs/jb/lib/python3.10/site-packages/pyscf/lib/libnp_helper.dylib, 6): Library not loaded: /usr/local/opt/libomp/lib/libomp.dylib
  Referenced from: /Users/brenda/opt/anaconda3/envs/jb/lib/python3.10/site-packages/pyscf/lib/libnp_helper.dylib
  Reason: image not found

